<?xml version="1.0" ?>
<!-- =================================================================================== -->
<!-- |    This document was autogenerated by xacro from doublearm6.xacro               | -->
<!-- |    EDITING THIS FILE BY HAND IS NOT RECOMMENDED                                 | -->
<!-- =================================================================================== -->
<robot name="doublearm6">
  <material name="silver">
    <color rgba="0.700 0.700 0.700 1.000"/>
  </material>
  <transmission name="l1_tran">
    <type>transmission_interface/SimpleTransmission</type>
    <joint name="l1">
      <hardwareInterface>hardware_interface/EffortJointInterface</hardwareInterface>
    </joint>
    <actuator name="l1_actr">
      <hardwareInterface>hardware_interface/EffortJointInterface</hardwareInterface>
      <mechanicalReduction>1</mechanicalReduction>
    </actuator>
  </transmission>
  <transmission name="l2_tran">
    <type>transmission_interface/SimpleTransmission</type>
    <joint name="l2">
      <hardwareInterface>hardware_interface/EffortJointInterface</hardwareInterface>
    </joint>
    <actuator name="l2_actr">
      <hardwareInterface>hardware_interface/EffortJointInterface</hardwareInterface>
      <mechanicalReduction>1</mechanicalReduction>
    </actuator>
  </transmission>
  <transmission name="l4_tran">
    <type>transmission_interface/SimpleTransmission</type>
    <joint name="l4">
      <hardwareInterface>hardware_interface/EffortJointInterface</hardwareInterface>
    </joint>
    <actuator name="l4_actr">
      <hardwareInterface>hardware_interface/EffortJointInterface</hardwareInterface>
      <mechanicalReduction>1</mechanicalReduction>
    </actuator>
  </transmission>
  <transmission name="r1_tran">
    <type>transmission_interface/SimpleTransmission</type>
    <joint name="r1">
      <hardwareInterface>hardware_interface/EffortJointInterface</hardwareInterface>
    </joint>
    <actuator name="r1_actr">
      <hardwareInterface>hardware_interface/EffortJointInterface</hardwareInterface>
      <mechanicalReduction>1</mechanicalReduction>
    </actuator>
  </transmission>
  <transmission name="r2_tran">
    <type>transmission_interface/SimpleTransmission</type>
    <joint name="r2">
      <hardwareInterface>hardware_interface/EffortJointInterface</hardwareInterface>
    </joint>
    <actuator name="r2_actr">
      <hardwareInterface>hardware_interface/EffortJointInterface</hardwareInterface>
      <mechanicalReduction>1</mechanicalReduction>
    </actuator>
  </transmission>
  <transmission name="r4_tran">
    <type>transmission_interface/SimpleTransmission</type>
    <joint name="r4">
      <hardwareInterface>hardware_interface/EffortJointInterface</hardwareInterface>
    </joint>
    <actuator name="r4_actr">
      <hardwareInterface>hardware_interface/EffortJointInterface</hardwareInterface>
      <mechanicalReduction>1</mechanicalReduction>
    </actuator>
  </transmission>
  <transmission name="r3_tran">
    <type>transmission_interface/SimpleTransmission</type>
    <joint name="r3">
      <hardwareInterface>hardware_interface/EffortJointInterface</hardwareInterface>
    </joint>
    <actuator name="r3_actr">
      <hardwareInterface>hardware_interface/EffortJointInterface</hardwareInterface>
      <mechanicalReduction>1</mechanicalReduction>
    </actuator>
  </transmission>
  <transmission name="l3_tran">
    <type>transmission_interface/SimpleTransmission</type>
    <joint name="l3">
      <hardwareInterface>hardware_interface/EffortJointInterface</hardwareInterface>
    </joint>
    <actuator name="l3_actr">
      <hardwareInterface>hardware_interface/EffortJointInterface</hardwareInterface>
      <mechanicalReduction>1</mechanicalReduction>
    </actuator>
  </transmission>
  <transmission name="l5_tran">
    <type>transmission_interface/SimpleTransmission</type>
    <joint name="l5">
      <hardwareInterface>hardware_interface/EffortJointInterface</hardwareInterface>
    </joint>
    <actuator name="l5_actr">
      <hardwareInterface>hardware_interface/EffortJointInterface</hardwareInterface>
      <mechanicalReduction>1</mechanicalReduction>
    </actuator>
  </transmission>
  <transmission name="r5_tran">
    <type>transmission_interface/SimpleTransmission</type>
    <joint name="r5">
      <hardwareInterface>hardware_interface/EffortJointInterface</hardwareInterface>
    </joint>
    <actuator name="r5_actr">
      <hardwareInterface>hardware_interface/EffortJointInterface</hardwareInterface>
      <mechanicalReduction>1</mechanicalReduction>
    </actuator>
  </transmission>
  <gazebo>
    <plugin filename="libgazebo_ros_control.so" name="control"/>
  </gazebo>
  <gazebo reference="huagan">
    <material>Gazebo/Silver</material>
    <mu1>0.2</mu1>
    <mu2>0.2</mu2>
    <self_collide>true</self_collide>
    <gravity>true</gravity>
  </gazebo>
  <gazebo reference="link_l1_1">
    <material>Gazebo/Silver</material>
    <mu1>0.2</mu1>
    <mu2>0.2</mu2>
    <self_collide>true</self_collide>
  </gazebo>
  <gazebo reference="link_l2_1">
    <material>Gazebo/Silver</material>
    <mu1>0.2</mu1>
    <mu2>0.2</mu2>
    <self_collide>true</self_collide>
  </gazebo>
  <gazebo reference="link_l3_1">
    <material>Gazebo/Silver</material>
    <mu1>0.2</mu1>
    <mu2>0.2</mu2>
    <self_collide>true</self_collide>
  </gazebo>
  <gazebo reference="link_l5_1">
    <material>Gazebo/Silver</material>
    <mu1>0.2</mu1>
    <mu2>0.2</mu2>
    <self_collide>true</self_collide>
  </gazebo>
  <gazebo reference="link_r1_2">
    <material>Gazebo/Silver</material>
    <mu1>0.2</mu1>
    <mu2>0.2</mu2>
    <self_collide>true</self_collide>
  </gazebo>
  <gazebo reference="link_r2_2">
    <material>Gazebo/Silver</material>
    <mu1>0.2</mu1>
    <mu2>0.2</mu2>
    <self_collide>true</self_collide>
  </gazebo>
  <gazebo reference="link_r3_2">
    <material>Gazebo/Silver</material>
    <mu1>0.2</mu1>
    <mu2>0.2</mu2>
    <self_collide>true</self_collide>
  </gazebo>
  <gazebo reference="link_r5_2">
    <material>Gazebo/Silver</material>
    <mu1>0.2</mu1>
    <mu2>0.2</mu2>
    <self_collide>true</self_collide>
  </gazebo>
  <gazebo reference="link_r4_2">
    <material>Gazebo/Silver</material>
    <mu1>0.2</mu1>
    <mu2>0.2</mu2>
    <self_collide>true</self_collide>
  </gazebo>
  <gazebo reference="link_l4_1">
    <material>Gazebo/Silver</material>
    <mu1>0.2</mu1>
    <mu2>0.2</mu2>
    <self_collide>true</self_collide>
  </gazebo>
  <gazebo reference="huagan_1">
    <material>Gazebo/Silver</material>
    <mu1>0.2</mu1>
    <mu2>0.2</mu2>
    <self_collide>true</self_collide>
  </gazebo>
  <gazebo reference="link_l6_1">
    <material>Gazebo/Silver</material>
    <mu1>0.2</mu1>
    <mu2>0.2</mu2>
    <self_collide>true</self_collide>
  </gazebo>
  <gazebo reference="link_l7_1">
    <material>Gazebo/Silver</material>
    <mu1>0.2</mu1>
    <mu2>0.2</mu2>
    <self_collide>true</self_collide>
  </gazebo>
  <gazebo reference="link_r6_1">
    <material>Gazebo/Silver</material>
    <mu1>0.2</mu1>
    <mu2>0.2</mu2>
    <self_collide>true</self_collide>
  </gazebo>
  <gazebo reference="link_r7_1">
    <material>Gazebo/Silver</material>
    <mu1>0.2</mu1>
    <mu2>0.2</mu2>
    <self_collide>true</self_collide>
  </gazebo>
  <gazebo reference="link_l8_1">
    <material>Gazebo/Silver</material>
    <mu1>0.2</mu1>
    <mu2>0.2</mu2>
    <self_collide>true</self_collide>
  </gazebo>
  <gazebo reference="link_r8_1">
    <material>Gazebo/Silver</material>
    <mu1>0.2</mu1>
    <mu2>0.2</mu2>
    <self_collide>true</self_collide>
  </gazebo>
  <link name="huagan">
    <visual>
      <origin rpy="0 0 0" xyz="0 0 0"/>
      <geometry>
        <mesh filename="file:///home/swen/urdf_ws/install/doublearm6_description/share/doublearm6_description/meshes/base_link.stl" scale="0.001 0.001 0.001"/>
      </geometry>
      <material name="silver"/>
    </visual>
    <collision>
      <origin rpy="0 0 0" xyz="0 0 0"/>
      <geometry>
        <mesh filename="file:///home/swen/urdf_ws/install/doublearm6_description/share/doublearm6_description/meshes/base_link.stl" scale="0.001 0.001 0.001"/>
      </geometry>
    </collision>
  </link>
  <link name="link_l1_1">
    <inertial>
      <origin rpy="0 0 0" xyz="-0.03793332038532773 -0.037871637356570745 0.04578503235142668"/>
      <mass value="0.5725405286418096"/>
      <inertia ixx="0.000559" ixy="-1.4e-05" ixz="-1.8e-05" iyy="0.000559" iyz="-1.8e-05" izz="0.0008"/>
    </inertial>
    <visual>
      <origin rpy="0 0 0" xyz="-0.091 -0.11 -0.081"/>
      <geometry>
        <mesh filename="file:///home/swen/urdf_ws/install/doublearm6_description/share/doublearm6_description/meshes/link_l1_1.stl" scale="0.001 0.001 0.001"/>
      </geometry>
      <material name="silver"/>
    </visual>
    <collision>
      <origin rpy="0 0 0" xyz="-0.091 -0.11 -0.081"/>
      <geometry>
        <mesh filename="file:///home/swen/urdf_ws/install/doublearm6_description/share/doublearm6_description/meshes/link_l1_1.stl" scale="0.001 0.001 0.001"/>
      </geometry>
    </collision>
  </link>
  <link name="link_l2_1">
    <inertial>
      <origin rpy="0 0 0" xyz="-0.0005207139614030395 -0.0011164287562245717 0.018149382974876976"/>
      <mass value="0.42619982491457814"/>
      <inertia ixx="0.000148" ixy="0.0" ixz="0.0" iyy="0.000149" iyz="6e-06" izz="0.00015"/>
    </inertial>
    <visual>
      <origin rpy="0 0 0" xyz="-0.055998 -0.074998 -0.1505"/>
      <geometry>
        <mesh filename="file:///home/swen/urdf_ws/install/doublearm6_description/share/doublearm6_description/meshes/link_l2_1.stl" scale="0.001 0.001 0.001"/>
      </geometry>
      <material name="silver"/>
    </visual>
    <collision>
      <origin rpy="0 0 0" xyz="-0.055998 -0.074998 -0.1505"/>
      <geometry>
        <mesh filename="file:///home/swen/urdf_ws/install/doublearm6_description/share/doublearm6_description/meshes/link_l2_1.stl" scale="0.001 0.001 0.001"/>
      </geometry>
    </collision>
  </link>
  <link name="link_l3_1">
    <inertial>
      <origin rpy="0 0 0" xyz="2.142431840962411e-07 0.020769849687359627 0.05419211875747576"/>
      <mass value="0.1621736007348496"/>
      <inertia ixx="0.000276" ixy="0.0" ixz="0.0" iyy="0.000222" iyz="-0.0" izz="6.7e-05"/>
    </inertial>
    <visual>
      <origin rpy="0 0 0" xyz="-0.045498 -0.053498 -0.1812"/>
      <geometry>
        <mesh filename="file:///home/swen/urdf_ws/install/doublearm6_description/share/doublearm6_description/meshes/link_l3_1.stl" scale="0.001 0.001 0.001"/>
      </geometry>
      <material name="silver"/>
    </visual>
    <collision>
      <origin rpy="0 0 0" xyz="-0.045498 -0.053498 -0.1812"/>
      <geometry>
        <mesh filename="file:///home/swen/urdf_ws/install/doublearm6_description/share/doublearm6_description/meshes/link_l3_1.stl" scale="0.001 0.001 0.001"/>
      </geometry>
    </collision>
  </link>
  <link name="link_l5_1">
    <inertial>
      <origin rpy="0 0 0" xyz="3.356788170622016e-07 0.013862584192221826 0.02233739968169607"/>
      <mass value="0.07341722198230313"/>
      <inertia ixx="5.6e-05" ixy="0.0" ixz="-0.0" iyy="3.5e-05" iyz="-0.0" izz="2.8e-05"/>
    </inertial>
    <visual>
      <origin rpy="0 0 0" xyz="-0.045498 -0.060248 -0.3858"/>
      <geometry>
        <mesh filename="file:///home/swen/urdf_ws/install/doublearm6_description/share/doublearm6_description/meshes/link_l5_1.stl" scale="0.001 0.001 0.001"/>
      </geometry>
      <material name="silver"/>
    </visual>
    <collision>
      <origin rpy="0 0 0" xyz="-0.045498 -0.060248 -0.3858"/>
      <geometry>
        <mesh filename="file:///home/swen/urdf_ws/install/doublearm6_description/share/doublearm6_description/meshes/link_l5_1.stl" scale="0.001 0.001 0.001"/>
      </geometry>
    </collision>
  </link>
  <link name="link_r1_2">
    <inertial>
      <origin rpy="0 0 0" xyz="0.032423804342822826 0.03248548737143005 0.04578503235142707"/>
      <mass value="0.5725405286418096"/>
      <inertia ixx="0.000559" ixy="-1.4e-05" ixz="-1.8e-05" iyy="0.000559" iyz="-1.8e-05" izz="0.0008"/>
    </inertial>
    <visual>
      <origin rpy="0 0 0" xyz="-0.021 0.11 -0.081"/>
      <geometry>
        <mesh filename="file:///home/swen/urdf_ws/install/doublearm6_description/share/doublearm6_description/meshes/link_r1_2.stl" scale="0.001 0.001 0.001"/>
      </geometry>
      <material name="silver"/>
    </visual>
    <collision>
      <origin rpy="0 0 0" xyz="-0.021 0.11 -0.081"/>
      <geometry>
        <mesh filename="file:///home/swen/urdf_ws/install/doublearm6_description/share/doublearm6_description/meshes/link_r1_2.stl" scale="0.001 0.001 0.001"/>
      </geometry>
    </collision>
  </link>
  <link name="link_r2_2">
    <inertial>
      <origin rpy="0 0 0" xyz="-0.0005205892332521209 -0.0011163040282242548 0.01814938297487731"/>
      <mass value="0.42619982491457814"/>
      <inertia ixx="0.000148" ixy="0.0" ixz="0.0" iyy="0.000149" iyz="6e-06" izz="0.00015"/>
    </inertial>
    <visual>
      <origin rpy="0 0 0" xyz="-0.056355 0.074645 -0.1505"/>
      <geometry>
        <mesh filename="file:///home/swen/urdf_ws/install/doublearm6_description/share/doublearm6_description/meshes/link_r2_2.stl" scale="0.001 0.001 0.001"/>
      </geometry>
      <material name="silver"/>
    </visual>
    <collision>
      <origin rpy="0 0 0" xyz="-0.056355 0.074645 -0.1505"/>
      <geometry>
        <mesh filename="file:///home/swen/urdf_ws/install/doublearm6_description/share/doublearm6_description/meshes/link_r2_2.stl" scale="0.001 0.001 0.001"/>
      </geometry>
    </collision>
  </link>
  <link name="link_r3_2">
    <inertial>
      <origin rpy="0 0 0" xyz="3.389667726227952e-07 0.02075593734889286 0.04772755616315025"/>
      <mass value="0.15416928313954215"/>
      <inertia ixx="0.000229" ixy="0.0" ixz="0.0" iyy="0.00018" iyz="-0.0" izz="6.1e-05"/>
    </inertial>
    <visual>
      <origin rpy="0 0 0" xyz="-0.045855 0.096145 -0.1812"/>
      <geometry>
        <mesh filename="file:///home/swen/urdf_ws/install/doublearm6_description/share/doublearm6_description/meshes/link_r3_2.stl" scale="0.001 0.001 0.001"/>
      </geometry>
      <material name="silver"/>
    </visual>
    <collision>
      <origin rpy="0 0 0" xyz="-0.045855 0.096145 -0.1812"/>
      <geometry>
        <mesh filename="file:///home/swen/urdf_ws/install/doublearm6_description/share/doublearm6_description/meshes/link_r3_2.stl" scale="0.001 0.001 0.001"/>
      </geometry>
    </collision>
  </link>
  <link name="link_r5_2">
    <inertial>
      <origin rpy="0 0 0" xyz="4.737695253331786e-07 0.013857055697345438 0.02273700368943865"/>
      <mass value="0.07244794276885677"/>
      <inertia ixx="5.6e-05" ixy="0.0" ixz="-0.0" iyy="3.5e-05" iyz="-0.0" izz="2.8e-05"/>
    </inertial>
    <visual>
      <origin rpy="0 0 0" xyz="-0.045855 0.089395 -0.3756"/>
      <geometry>
        <mesh filename="file:///home/swen/urdf_ws/install/doublearm6_description/share/doublearm6_description/meshes/link_r5_2.stl" scale="0.001 0.001 0.001"/>
      </geometry>
      <material name="silver"/>
    </visual>
    <collision>
      <origin rpy="0 0 0" xyz="-0.045855 0.089395 -0.3756"/>
      <geometry>
        <mesh filename="file:///home/swen/urdf_ws/install/doublearm6_description/share/doublearm6_description/meshes/link_r5_2.stl" scale="0.001 0.001 0.001"/>
      </geometry>
    </collision>
  </link>
  <link name="link_r4_2">
    <inertial>
      <origin rpy="0 0 0" xyz="3.1569969187787705e-05 0.01411672606458067 0.04747053928862227"/>
      <mass value="0.6421039903920133"/>
      <inertia ixx="0.000609" ixy="0.0" ixz="-0.0" iyy="0.000609" iyz="-0.0" izz="8.5e-05"/>
    </inertial>
    <visual>
      <origin rpy="0 0 0" xyz="-0.045855 0.089395 -0.2796"/>
      <geometry>
        <mesh filename="file:///home/swen/urdf_ws/install/doublearm6_description/share/doublearm6_description/meshes/link_r4_2.stl" scale="0.001 0.001 0.001"/>
      </geometry>
      <material name="silver"/>
    </visual>
    <collision>
      <origin rpy="0 0 0" xyz="-0.045855 0.089395 -0.2796"/>
      <geometry>
        <mesh filename="file:///home/swen/urdf_ws/install/doublearm6_description/share/doublearm6_description/meshes/link_r4_2.stl" scale="0.001 0.001 0.001"/>
      </geometry>
    </collision>
  </link>
  <link name="link_l4_1">
    <inertial>
      <origin rpy="0 0 0" xyz="3.144524103594615e-05 0.014116601336580041 0.04747053928862105"/>
      <mass value="0.6421039903920133"/>
      <inertia ixx="0.000609" ixy="0.0" ixz="-0.0" iyy="0.000609" iyz="-0.0" izz="8.5e-05"/>
    </inertial>
    <visual>
      <origin rpy="0 0 0" xyz="-0.045498 -0.060248 -0.2898"/>
      <geometry>
        <mesh filename="file:///home/swen/urdf_ws/install/doublearm6_description/share/doublearm6_description/meshes/link_l4_1.stl" scale="0.001 0.001 0.001"/>
      </geometry>
      <material name="silver"/>
    </visual>
    <collision>
      <origin rpy="0 0 0" xyz="-0.045498 -0.060248 -0.2898"/>
      <geometry>
        <mesh filename="file:///home/swen/urdf_ws/install/doublearm6_description/share/doublearm6_description/meshes/link_l4_1.stl" scale="0.001 0.001 0.001"/>
      </geometry>
    </collision>
  </link>
  <link name="huagan_1">
    <inertial>
      <origin rpy="0 0 0" xyz="0.026062371171957182 -2.2510193602442995e-08 0.02958292769303884"/>
      <mass value="1.0213757891414847"/>
      <inertia ixx="0.006064" ixy="-0.0" ixz="-0.000524" iyy="0.001832" iyz="-0.0" izz="0.006122"/>
    </inertial>
    <visual>
      <origin rpy="0 0 0" xyz="-0.005 0.0 -0.027"/>
      <geometry>
        <mesh filename="file:///home/swen/urdf_ws/install/doublearm6_description/share/doublearm6_description/meshes/huagan_1.stl" scale="0.001 0.001 0.001"/>
      </geometry>
      <material name="silver"/>
    </visual>
    <collision>
      <origin rpy="0 0 0" xyz="-0.005 0.0 -0.027"/>
      <geometry>
        <mesh filename="file:///home/swen/urdf_ws/install/doublearm6_description/share/doublearm6_description/meshes/huagan_1.stl" scale="0.001 0.001 0.001"/>
      </geometry>
    </collision>
  </link>
  <link name="link_l6_1">
    <inertial>
      <origin rpy="0 0 0" xyz="-4.219824397556915e-06 4.861755351068253e-06 0.0009999999999989462"/>
      <mass value="0.0012269853788458628"/>
      <inertia ixx="0.0" ixy="-0.0" ixz="-0.0" iyy="0.0" iyz="0.0" izz="0.0"/>
    </inertial>
    <visual>
      <origin rpy="0 0 0" xyz="-0.045498 -0.074348 -0.4365"/>
      <geometry>
        <mesh filename="file:///home/swen/urdf_ws/install/doublearm6_description/share/doublearm6_description/meshes/link_l6_1.stl" scale="0.001 0.001 0.001"/>
      </geometry>
      <material name="silver"/>
    </visual>
    <collision>
      <origin rpy="0 0 0" xyz="-0.045498 -0.074348 -0.4365"/>
      <geometry>
        <mesh filename="file:///home/swen/urdf_ws/install/doublearm6_description/share/doublearm6_description/meshes/link_l6_1.stl" scale="0.001 0.001 0.001"/>
      </geometry>
    </collision>
  </link>
  <link name="link_l7_1">
    <inertial>
      <origin rpy="0 0 0" xyz="-0.00029464905851634554 -0.0006234325772860455 0.027633060488336914"/>
      <mass value="0.08182541987264973"/>
      <inertia ixx="4.2e-05" ixy="-0.0" ixz="-0.0" iyy="3.4e-05" iyz="2e-06" izz="1.1e-05"/>
    </inertial>
    <visual>
      <origin rpy="0 0 0" xyz="-0.045498 -0.074348 -0.4385"/>
      <geometry>
        <mesh filename="file:///home/swen/urdf_ws/install/doublearm6_description/share/doublearm6_description/meshes/link_l7_1.stl" scale="0.001 0.001 0.001"/>
      </geometry>
      <material name="silver"/>
    </visual>
    <collision>
      <origin rpy="0 0 0" xyz="-0.045498 -0.074348 -0.4385"/>
      <geometry>
        <mesh filename="file:///home/swen/urdf_ws/install/doublearm6_description/share/doublearm6_description/meshes/link_l7_1.stl" scale="0.001 0.001 0.001"/>
      </geometry>
    </collision>
  </link>
  <link name="link_r6_1">
    <inertial>
      <origin rpy="0 0 0" xyz="-4.095096246534147e-06 4.986483348554116e-06 0.001000000000000112"/>
      <mass value="0.0012269853788458589"/>
      <inertia ixx="0.0" ixy="-0.0" ixz="0.0" iyy="0.0" iyz="0.0" izz="0.0"/>
    </inertial>
    <visual>
      <origin rpy="0 0 0" xyz="-0.045855 0.075295 -0.4263"/>
      <geometry>
        <mesh filename="file:///home/swen/urdf_ws/install/doublearm6_description/share/doublearm6_description/meshes/link_r6_1.stl" scale="0.001 0.001 0.001"/>
      </geometry>
      <material name="silver"/>
    </visual>
    <collision>
      <origin rpy="0 0 0" xyz="-0.045855 0.075295 -0.4263"/>
      <geometry>
        <mesh filename="file:///home/swen/urdf_ws/install/doublearm6_description/share/doublearm6_description/meshes/link_r6_1.stl" scale="0.001 0.001 0.001"/>
      </geometry>
    </collision>
  </link>
  <link name="link_r7_1">
    <inertial>
      <origin rpy="0 0 0" xyz="0.00026102080165230773 -0.0004751890023281108 0.024878450064164337"/>
      <mass value="0.07059138817324344"/>
      <inertia ixx="3.1e-05" ixy="-0.0" ixz="0.0" iyy="2.4e-05" iyz="1e-06" izz="8e-06"/>
    </inertial>
    <visual>
      <origin rpy="0 0 0" xyz="-0.045855 0.075295 -0.4283"/>
      <geometry>
        <mesh filename="file:///home/swen/urdf_ws/install/doublearm6_description/share/doublearm6_description/meshes/link_r7_1.stl" scale="0.001 0.001 0.001"/>
      </geometry>
      <material name="silver"/>
    </visual>
    <collision>
      <origin rpy="0 0 0" xyz="-0.045855 0.075295 -0.4283"/>
      <geometry>
        <mesh filename="file:///home/swen/urdf_ws/install/doublearm6_description/share/doublearm6_description/meshes/link_r7_1.stl" scale="0.001 0.001 0.001"/>
      </geometry>
    </collision>
  </link>
  <link name="link_l8_1">
    <inertial>
      <origin rpy="0 0 0" xyz="-0.08474400807689672 -0.020399816306156712 -0.507459999999996"/>
      <mass value="6.165375582648934e-12"/>
      <inertia ixx="0.0" ixy="0.0" ixz="0.0" iyy="0.0" iyz="0.0" izz="0.0"/>
    </inertial>
    <visual>
      <origin rpy="0 0 0" xyz="-0.045498 -0.074348 -0.50746"/>
      <geometry>
        <mesh filename="file:///home/swen/urdf_ws/install/doublearm6_description/share/doublearm6_description/meshes/link_l8_1.stl" scale="0.001 0.001 0.001"/>
      </geometry>
      <material name="silver"/>
    </visual>
    <collision>
      <origin rpy="0 0 0" xyz="-0.045498 -0.074348 -0.50746"/>
      <geometry>
        <mesh filename="file:///home/swen/urdf_ws/install/doublearm6_description/share/doublearm6_description/meshes/link_l8_1.stl" scale="0.001 0.001 0.001"/>
      </geometry>
    </collision>
  </link>
  <link name="link_r8_1">
    <inertial>
      <origin rpy="0 0 0" xyz="-0.08566564748164562 0.02081708319514966 -0.49315999999999616"/>
      <mass value="6.165375582648934e-12"/>
      <inertia ixx="0.0" ixy="-0.0" ixz="0.0" iyy="0.0" iyz="0.0" izz="0.0"/>
    </inertial>
    <visual>
      <origin rpy="0 0 0" xyz="-0.045855 0.075295 -0.49316"/>
      <geometry>
        <mesh filename="file:///home/swen/urdf_ws/install/doublearm6_description/share/doublearm6_description/meshes/link_r8_1.stl" scale="0.001 0.001 0.001"/>
      </geometry>
      <material name="silver"/>
    </visual>
    <collision>
      <origin rpy="0 0 0" xyz="-0.045855 0.075295 -0.49316"/>
      <geometry>
        <mesh filename="file:///home/swen/urdf_ws/install/doublearm6_description/share/doublearm6_description/meshes/link_r8_1.stl" scale="0.001 0.001 0.001"/>
      </geometry>
    </collision>
  </link>
  <joint name="fixed_l1" type="fixed">
    <origin rpy="0 0 0" xyz="0.086 0.11 0.054"/>
    <parent link="huagan_1"/>
    <child link="link_l1_1"/>
  </joint>
  <joint name="l1" type="revolute">
    <origin rpy="0 0 0" xyz="-0.035002 -0.035002 0.0695"/>
    <parent link="link_l1_1"/>
    <child link="link_l2_1"/>
    <axis xyz="0.0 -0.0 -1.0"/>
    <limit effort="100" lower="-2.09439506" upper="2.09439506" velocity="10.000001"/>
  </joint>
  <joint name="l2" type="revolute">
    <origin rpy="0 0 0" xyz="-0.0105 -0.0215 0.0307"/>
    <parent link="link_l2_1"/>
    <child link="link_l3_1"/>
    <axis xyz="0.0 1.0 0.0"/>
    <limit effort="100" lower="-2.09439506" upper="2.09439506" velocity="10.000001"/>
  </joint>
  <joint name="l4" type="revolute">
    <origin rpy="0 0 0" xyz="0.0 0.0 0.096"/>
    <parent link="link_l4_1"/>
    <child link="link_l5_1"/>
    <axis xyz="0.0 1.0 0.0"/>
    <limit effort="100" lower="-2.09439506" upper="2.09439506" velocity="10.000001"/>
  </joint>
  <joint name="fixed_r1" type="fixed">
    <origin rpy="0 0 0" xyz="0.016 -0.11 0.054"/>
    <parent link="huagan_1"/>
    <child link="link_r1_2"/>
  </joint>
  <joint name="r1" type="revolute">
    <origin rpy="0 0 0" xyz="0.035355 0.035355 0.0695"/>
    <parent link="link_r1_2"/>
    <child link="link_r2_2"/>
    <axis xyz="0.0 0.0 -1.0"/>
    <limit effort="100" lower="-2.09439506" upper="2.09439506" velocity="10.000001"/>
  </joint>
  <joint name="r2" type="revolute">
    <origin rpy="0 0 0" xyz="-0.0105 -0.0215 0.0307"/>
    <parent link="link_r2_2"/>
    <child link="link_r3_2"/>
    <axis xyz="0.0 1.0 -0.0"/>
    <limit effort="100" lower="-2.09439506" upper="2.09439506" velocity="10.000001"/>
  </joint>
  <joint name="r4" type="revolute">
    <origin rpy="0 0 0" xyz="0.0 0.0 0.096"/>
    <parent link="link_r4_2"/>
    <child link="link_r5_2"/>
    <axis xyz="0.0 1.0 0.0"/>
    <limit effort="100" lower="-2.09439506" upper="2.09439506" velocity="10.000001"/>
  </joint>
  <joint name="r3" type="revolute">
    <origin rpy="0 0 0" xyz="0.0 0.00675 0.0984"/>
    <parent link="link_r3_2"/>
    <child link="link_r4_2"/>
    <axis xyz="0.0 1.0 0.0"/>
    <limit effort="100" lower="-2.09439506" upper="2.09439506" velocity="10.000001"/>
  </joint>
  <joint name="l3" type="revolute">
    <origin rpy="0 0 0" xyz="0.0 0.00675 0.1086"/>
    <parent link="link_l3_1"/>
    <child link="link_l4_1"/>
    <axis xyz="0.0 1.0 0.0"/>
    <limit effort="100" lower="-2.09439506" upper="2.09439506" velocity="10.000001"/>
  </joint>
  <joint name="fixed_base" type="fixed">
    <origin rpy="0 0 0" xyz="0.005 0.0 0.027"/>
    <parent link="huagan"/>
    <child link="huagan_1"/>
  </joint>
  <joint name="l5" type="revolute">
    <origin rpy="0 0 0" xyz="0.0 0.0141 0.0507"/>
    <parent link="link_l5_1"/>
    <child link="link_l6_1"/>
    <axis xyz="0.0 0.0 -1.0"/>
    <limit effort="100" lower="-2.09439506" upper="2.09439506" velocity="10.000001"/>
  </joint>
  <joint name="fixed_l2" type="fixed">
    <origin rpy="0 0 0" xyz="0.0 0.0 0.002"/>
    <parent link="link_l6_1"/>
    <child link="link_l7_1"/>
  </joint>
  <joint name="r5" type="revolute">
    <origin rpy="0 0 0" xyz="0.0 0.0141 0.0507"/>
    <parent link="link_r5_2"/>
    <child link="link_r6_1"/>
    <axis xyz="0.0 0.0 -1.0"/>
    <limit effort="100" lower="-2.09439506" upper="2.09439506" velocity="10.000001"/>
  </joint>
  <joint name="fixed_r2" type="fixed">
    <origin rpy="0 0 0" xyz="0.0 0.0 0.002"/>
    <parent link="link_r6_1"/>
    <child link="link_r7_1"/>
  </joint>
  <joint name="fixed_l3" type="fixed">
    <origin rpy="0 0 0" xyz="0.0 0.0 0.06896"/>
    <parent link="link_l7_1"/>
    <child link="link_l8_1"/>
  </joint>
  <joint name="fixed_r3" type="fixed">
    <origin rpy="0 0 0" xyz="0.0 0.0 0.06486"/>
    <parent link="link_r7_1"/>
    <child link="link_r8_1"/>
  </joint>
</robot>
